[2023-06-28T12:38:11.801+0000] {taskinstance.py:1087} INFO - Dependencies all met for <TaskInstance: predict_rates.generate_predictions_view manual__2023-06-28T12:36:41.443873+00:00 [queued]>
[2023-06-28T12:38:11.808+0000] {taskinstance.py:1087} INFO - Dependencies all met for <TaskInstance: predict_rates.generate_predictions_view manual__2023-06-28T12:36:41.443873+00:00 [queued]>
[2023-06-28T12:38:11.809+0000] {taskinstance.py:1283} INFO - 
--------------------------------------------------------------------------------
[2023-06-28T12:38:11.809+0000] {taskinstance.py:1284} INFO - Starting attempt 2 of 2
[2023-06-28T12:38:11.809+0000] {taskinstance.py:1285} INFO - 
--------------------------------------------------------------------------------
[2023-06-28T12:38:11.822+0000] {taskinstance.py:1304} INFO - Executing <Task(_PythonDecoratedOperator): generate_predictions_view> on 2023-06-28 12:36:41.443873+00:00
[2023-06-28T12:38:11.827+0000] {standard_task_runner.py:55} INFO - Started process 936 to run task
[2023-06-28T12:38:11.831+0000] {standard_task_runner.py:82} INFO - Running: ['***', 'tasks', 'run', 'predict_rates', 'generate_predictions_view', 'manual__2023-06-28T12:36:41.443873+00:00', '--job-id', '95', '--raw', '--subdir', 'DAGS_FOLDER/predict_rates.py', '--cfg-path', '/tmp/tmp52150iia']
[2023-06-28T12:38:11.834+0000] {standard_task_runner.py:83} INFO - Job 95: Subtask generate_predictions_view
[2023-06-28T12:38:11.892+0000] {task_command.py:389} INFO - Running <TaskInstance: predict_rates.generate_predictions_view manual__2023-06-28T12:36:41.443873+00:00 [running]> on host 3e2e38946fac
[2023-06-28T12:38:11.962+0000] {taskinstance.py:1513} INFO - Exporting the following env vars:
AIRFLOW_CTX_DAG_OWNER=***
AIRFLOW_CTX_DAG_ID=predict_rates
AIRFLOW_CTX_TASK_ID=generate_predictions_view
AIRFLOW_CTX_EXECUTION_DATE=2023-06-28T12:36:41.443873+00:00
AIRFLOW_CTX_TRY_NUMBER=2
AIRFLOW_CTX_DAG_RUN_ID=manual__2023-06-28T12:36:41.443873+00:00
[2023-06-28T12:38:11.963+0000] {taskinstance.py:1772} ERROR - Task failed with exception
Traceback (most recent call last):
  File "/home/airflow/.local/lib/python3.7/site-packages/airflow/decorators/base.py", line 217, in execute
    return_value = super().execute(context)
  File "/home/airflow/.local/lib/python3.7/site-packages/airflow/operators/python.py", line 175, in execute
    return_value = self.execute_callable()
  File "/home/airflow/.local/lib/python3.7/site-packages/airflow/operators/python.py", line 192, in execute_callable
    return self.python_callable(*self.op_args, **self.op_kwargs)
  File "/opt/airflow/dags/predict_rates.py", line 45, in generate_predictions_view
    _generate_predictions_view(prediction_df.from_dict(prediction_df))
AttributeError: 'str' object has no attribute 'from_dict'
[2023-06-28T12:38:11.971+0000] {taskinstance.py:1327} INFO - Marking task as FAILED. dag_id=predict_rates, task_id=generate_predictions_view, execution_date=20230628T123641, start_date=20230628T123811, end_date=20230628T123811
[2023-06-28T12:38:11.981+0000] {standard_task_runner.py:105} ERROR - Failed to execute job 95 for task generate_predictions_view ('str' object has no attribute 'from_dict'; 936)
[2023-06-28T12:38:12.001+0000] {local_task_job.py:159} INFO - Task exited with return code 1
[2023-06-28T12:38:12.015+0000] {taskinstance.py:2582} INFO - 0 downstream tasks scheduled from follow-on schedule check
